Workbook

Sheet Dashboard
B1: Enrollment Funnel Dashboard
B2: SYNTHETIC DATA (portfolio project) | Snapshot: 30-Aug-2026 | Only records flagged OK in Data_Quality are counted | Recent weeks are immature: later-stage conversions have not happened yet
B4: Total leads | C4: Contacted % | D4: Applications | E4: Admitted | F4: Enrolled | G4: Lead → Enrolled % | H4: Avg days to 1st contact
B5: =C9 -> 1593 | C5: =E10 -> 0.91274325 | D5: =C11 -> 284 | E5: =C12 -> 217 | F5: =C13 -> 117 | G5: =D13 -> 0.073446328 | H5: =IFERROR(AVERAGEIFS(Data!$M$2:$M$5000,Data!$N$2:$N$5000,"OK"),0) -> 1.5735901
B7: 1) ENROLLMENT FUNNEL
B8: Stage | C8: Count | D8: % of all leads | E8: vs previous stage
B9: Leads | C9: =COUNTIFS(Data!$N$2:$N$5000,"OK") -> 1593 | D9: =IFERROR(C9/$C$9,0) -> 1
B10: Contacted | C10: =COUNTIFS(Data!$N$2:$N$5000,"OK",Data!$G$2:$G$5000,"<>") -> 1454 | D10: =IFERROR(C10/$C$9,0) -> 0.91274325 | E10: =IFERROR(C10/C9,0) -> 0.91274325
B11: Applied | C11: =COUNTIFS(Data!$N$2:$N$5000,"OK",Data!$H$2:$H$5000,"<>") -> 284 | D11: =IFERROR(C11/$C$9,0) -> 0.17827997 | E11: =IFERROR(C11/C10,0) -> 0.19532325
B12: Admitted | C12: =COUNTIFS(Data!$N$2:$N$5000,"OK",Data!$I$2:$I$5000,"<>") -> 217 | D12: =IFERROR(C12/$C$9,0) -> 0.13622097 | E12: =IFERROR(C12/C11,0) -> 0.76408451
B13: Enrolled | C13: =COUNTIFS(Data!$N$2:$N$5000,"OK",Data!$J$2:$J$5000,"<>") -> 117 | D13: =IFERROR(C13/$C$9,0) -> 0.073446328 | E13: =IFERROR(C13/C12,0) -> 0.53917051
B15: 2) CONVERSION BY LEAD SOURCE (sorted by Lead → Enrolled)
B16: Source | C16: Leads | D16: Applications | E16: Enrolled | F16: Lead → App % | G16: App → Enrolled % | H16: Lead → Enrolled % | I16: Avg days to 1st contact
B17: Walk-in | C17: =COUNTIFS(Data!$N$2:$N$5000,"OK",Data!$C$2:$C$5000,$B17) -> 111 | D17: =COUNTIFS(Data!$N$2:$N$5000,"OK",Data!$C$2:$C$5000,$B17,Data!$H$2:$H$5000,"<>") -> 42 | E17: =COUNTIFS(Data!$N$2:$N$5000,"OK",Data!$C$2:$C$5000,$B17,Data!$J$2:$J$5000,"<>") -> 17 | F17: =IFERROR(D17/C17,0) -> 0.37837838 | G17: =IFERROR(E17/D17,0) -> 0.4047619 | H17: =IFERROR(E17/C17,0) -> 0.15315315 | I17: =IFERROR(AVERAGEIFS(Data!$M$2:$M$5000,Data!$N$2:$N$5000,"OK",Data!$C$2:$C$5000,$B17),0) -> 1.6132075
B18: Referral | C18: =COUNTIFS(Data!$N$2:$N$5000,"OK",Data!$C$2:$C$5000,$B18) -> 196 | D18: =COUNTIFS(Data!$N$2:$N$5000,"OK",Data!$C$2:$C$5000,$B18,Data!$H$2:$H$5000,"<>") -> 56 | E18: =COUNTIFS(Data!$N$2:$N$5000,"OK",Data!$C$2:$C$5000,$B18,Data!$J$2:$J$5000,"<>") -> 29 | F18: =IFERROR(D18/C18,0) -> 0.28571429 | G18: =IFERROR(E18/D18,0) -> 0.51785714 | H18: =IFERROR(E18/C18,0) -> 0.14795918 | I18: =IFERROR(AVERAGEIFS(Data!$M$2:$M$5000,Data!$N$2:$N$5000,"OK",Data!$C$2:$C$5000,$B18),0) -> 1.519774
B19: School Visit | C19: =COUNTIFS(Data!$N$2:$N$5000,"OK",Data!$C$2:$C$5000,$B19) -> 251 | D19: =COUNTIFS(Data!$N$2:$N$5000,"OK",Data!$C$2:$C$5000,$B19,Data!$H$2:$H$5000,"<>") -> 54 | E19: =COUNTIFS(Data!$N$2:$N$5000,"OK",Data!$C$2:$C$5000,$B19,Data!$J$2:$J$5000,"<>") -> 20 | F19: =IFERROR(D19/C19,0) -> 0.21513944 | G19: =IFERROR(E19/D19,0) -> 0.37037037 | H19: =IFERROR(E19/C19,0) -> 0.079681275 | I19: =IFERROR(AVERAGEIFS(Data!$M$2:$M$5000,Data!$N$2:$N$5000,"OK",Data!$C$2:$C$5000,$B19),0) -> 1.6371308
B20: Education Fair | C20: =COUNTIFS(Data!$N$2:$N$5000,"OK",Data!$C$2:$C$5000,$B20) -> 145 | D20: =COUNTIFS(Data!$N$2:$N$5000,"OK",Data!$C$2:$C$5000,$B20,Data!$H$2:$H$5000,"<>") -> 30 | E20: =COUNTIFS(Data!$N$2:$N$5000,"OK",Data!$C$2:$C$5000,$B20,Data!$J$2:$J$5000,"<>") -> 11 | F20: =IFERROR(D20/C20,0) -> 0.20689655 | G20: =IFERROR(E20/D20,0) -> 0.36666667 | H20: =IFERROR(E20/C20,0) -> 0.075862069 | I20: =IFERROR(AVERAGEIFS(Data!$M$2:$M$5000,Data!$N$2:$N$5000,"OK",Data!$C$2:$C$5000,$B20),0) -> 1.7122302
B21: Google Ads | C21: =COUNTIFS(Data!$N$2:$N$5000,"OK",Data!$C$2:$C$5000,$B21) -> 253 | D21: =COUNTIFS(Data!$N$2:$N$5000,"OK",Data!$C$2:$C$5000,$B21,Data!$H$2:$H$5000,"<>") -> 28 | E21: =COUNTIFS(Data!$N$2:$N$5000,"OK",Data!$C$2:$C$5000,$B21,Data!$J$2:$J$5000,"<>") -> 14 | F21: =IFERROR(D21/C21,0) -> 0.11067194 | G21: =IFERROR(E21/D21,0) -> 0.5 | H21: =IFERROR(E21/C21,0) -> 0.055335968 | I21: =IFERROR(AVERAGEIFS(Data!$M$2:$M$5000,Data!$N$2:$N$5000,"OK",Data!$C$2:$C$5000,$B21),0) -> 1.4808511
B22: Meta Ads | C22: =COUNTIFS(Data!$N$2:$N$5000,"OK",Data!$C$2:$C$5000,$B22) -> 434 | D22: =COUNTIFS(Data!$N$2:$N$5000,"OK",Data!$C$2:$C$5000,$B22,Data!$H$2:$H$5000,"<>") -> 49 | E22: =COUNTIFS(Data!$N$2:$N$5000,"OK",Data!$C$2:$C$5000,$B22,Data!$J$2:$J$5000,"<>") -> 19 | F22: =IFERROR(D22/C22,0) -> 0.11290323 | G22: =IFERROR(E22/D22,0) -> 0.3877551 | H22: =IFERROR(E22/C22,0) -> 0.043778802 | I22: =IFERROR(AVERAGEIFS(Data!$M$2:$M$5000,Data!$N$2:$N$5000,"OK",Data!$C$2:$C$5000,$B22),0) -> 1.4123989
B23: Website Organic | C23: =COUNTIFS(Data!$N$2:$N$5000,"OK",Data!$C$2:$C$5000,$B23) -> 203 | D23: =COUNTIFS(Data!$N$2:$N$5000,"OK",Data!$C$2:$C$5000,$B23,Data!$H$2:$H$5000,"<>") -> 25 | E23: =COUNTIFS(Data!$N$2:$N$5000,"OK",Data!$C$2:$C$5000,$B23,Data!$J$2:$J$5000,"<>") -> 7 | F23: =IFERROR(D23/C23,0) -> 0.12315271 | G23: =IFERROR(E23/D23,0) -> 0.28 | H23: =IFERROR(E23/C23,0) -> 0.034482759 | I23: =IFERROR(AVERAGEIFS(Data!$M$2:$M$5000,Data!$N$2:$N$5000,"OK",Data!$C$2:$C$5000,$B23),0) -> 1.8518519
B24: All sources | C24: =SUM(C17:C23) -> 1593 | D24: =SUM(D17:D23) -> 284 | E24: =SUM(E17:E23) -> 117 | F24: =IFERROR(D24/C24,0) -> 0.17827997 | G24: =IFERROR(E24/D24,0) -> 0.41197183 | H24: =IFERROR(E24/C24,0) -> 0.073446328 | I24: =IFERROR(AVERAGEIFS(Data!$M$2:$M$5000,Data!$N$2:$N$5000,"OK"),0) -> 1.5735901
B26: 3) CONVERSION BY PROGRAM (sorted by Lead → Enrolled)
B27: Program | C27: Leads | D27: Applications | E27: Admitted | F27: Enrolled | G27: Lead → App % | H27: App → Admit % | I27: Lead → Enrolled %
B28: Computer Science | C28: =COUNTIFS(Data!$N$2:$N$5000,"OK",Data!$D$2:$D$5000,$B28) -> 376 | D28: =COUNTIFS(Data!$N$2:$N$5000,"OK",Data!$D$2:$D$5000,$B28,Data!$H$2:$H$5000,"<>") -> 76 | E28: =COUNTIFS(Data!$N$2:$N$5000,"OK",Data!$D$2:$D$5000,$B28,Data!$I$2:$I$5000,"<>") -> 59 | F28: =COUNTIFS(Data!$N$2:$N$5000,"OK",Data!$D$2:$D$5000,$B28,Data!$J$2:$J$5000,"<>") -> 33 | G28: =IFERROR(D28/C28,0) -> 0.20212766 | H28: =IFERROR(E28/D28,0) -> 0.77631579 | I28: =IFERROR(F28/C28,0) -> 0.087765957
B29: Business Administration | C29: =COUNTIFS(Data!$N$2:$N$5000,"OK",Data!$D$2:$D$5000,$B29) -> 390 | D29: =COUNTIFS(Data!$N$2:$N$5000,"OK",Data!$D$2:$D$5000,$B29,Data!$H$2:$H$5000,"<>") -> 69 | E29: =COUNTIFS(Data!$N$2:$N$5000,"OK",Data!$D$2:$D$5000,$B29,Data!$I$2:$I$5000,"<>") -> 60 | F29: =COUNTIFS(Data!$N$2:$N$5000,"OK",Data!$D$2:$D$5000,$B29,Data!$J$2:$J$5000,"<>") -> 33 | G29: =IFERROR(D29/C29,0) -> 0.17692308 | H29: =IFERROR(E29/D29,0) -> 0.86956522 | I29: =IFERROR(F29/C29,0) -> 0.084615385
B30: Mass Communication | C30: =COUNTIFS(Data!$N$2:$N$5000,"OK",Data!$D$2:$D$5000,$B30) -> 203 | D30: =COUNTIFS(Data!$N$2:$N$5000,"OK",Data!$D$2:$D$5000,$B30,Data!$H$2:$H$5000,"<>") -> 40 | E30: =COUNTIFS(Data!$N$2:$N$5000,"OK",Data!$D$2:$D$5000,$B30,Data!$I$2:$I$5000,"<>") -> 28 | F30: =COUNTIFS(Data!$N$2:$N$5000,"OK",Data!$D$2:$D$5000,$B30,Data!$J$2:$J$5000,"<>") -> 15 | G30: =IFERROR(D30/C30,0) -> 0.19704433 | H30: =IFERROR(E30/D30,0) -> 0.7 | I30: =IFERROR(F30/C30,0) -> 0.073891626
B31: Health Sciences | C31: =COUNTIFS(Data!$N$2:$N$5000,"OK",Data!$D$2:$D$5000,$B31) -> 235 | D31: =COUNTIFS(Data!$N$2:$N$5000,"OK",Data!$D$2:$D$5000,$B31,Data!$H$2:$H$5000,"<>") -> 37 | E31: =COUNTIFS(Data!$N$2:$N$5000,"OK",Data!$D$2:$D$5000,$B31,Data!$I$2:$I$5000,"<>") -> 24 | F31: =COUNTIFS(Data!$N$2:$N$5000,"OK",Data!$D$2:$D$5000,$B31,Data!$J$2:$J$5000,"<>") -> 14 | G31: =IFERROR(D31/C31,0) -> 0.15744681 | H31: =IFERROR(E31/D31,0) -> 0.64864865 | I31: =IFERROR(F31/C31,0) -> 0.059574468
B32: Engineering | C32: =COUNTIFS(Data!$N$2:$N$5000,"OK",Data!$D$2:$D$5000,$B32) -> 389 | D32: =COUNTIFS(Data!$N$2:$N$5000,"OK",Data!$D$2:$D$5000,$B32,Data!$H$2:$H$5000,"<>") -> 62 | E32: =COUNTIFS(Data!$N$2:$N$5000,"OK",Data!$D$2:$D$5000,$B32,Data!$I$2:$I$5000,"<>") -> 46 | F32: =COUNTIFS(Data!$N$2:$N$5000,"OK",Data!$D$2:$D$5000,$B32,Data!$J$2:$J$5000,"<>") -> 22 | G32: =IFERROR(D32/C32,0) -> 0.15938303 | H32: =IFERROR(E32/D32,0) -> 0.74193548 | I32: =IFERROR(F32/C32,0) -> 0.05655527
B34: 4) FOLLOW-UP PERFORMANCE BY COUNSELOR
B35: Counselor | C35: Leads | D35: Avg days to 1st contact | E35: Avg follow-ups | F35: Lead → App % | G35: Lead → Enrolled %
B36: Counselor A | C36: =COUNTIFS(Data!$N$2:$N$5000,"OK",Data!$F$2:$F$5000,$B36) -> 253 | D36: =IFERROR(AVERAGEIFS(Data!$M$2:$M$5000,Data!$N$2:$N$5000,"OK",Data!$F$2:$F$5000,$B36),0) -> 0.45493562 | E36: =IFERROR(AVERAGEIFS(Data!$K$2:$K$5000,Data!$N$2:$N$5000,"OK",Data!$F$2:$F$5000,$B36,Data!$G$2:$G$5000,"<>"),0) -> 2.8497854 | F36: =IFERROR(COUNTIFS(Data!$N$2:$N$5000,"OK",Data!$F$2:$F$5000,$B36,Data!$H$2:$H$5000,"<>")/C36,0) -> 0.18181818 | G36: =IFERROR(COUNTIFS(Data!$N$2:$N$5000,"OK",Data!$F$2:$F$5000,$B36,Data!$J$2:$J$5000,"<>")/C36,0) -> 0.079051383
B37: Counselor B | C37: =COUNTIFS(Data!$N$2:$N$5000,"OK",Data!$F$2:$F$5000,$B37) -> 277 | D37: =IFERROR(AVERAGEIFS(Data!$M$2:$M$5000,Data!$N$2:$N$5000,"OK",Data!$F$2:$F$5000,$B37),0) -> 1.0039526 | E37: =IFERROR(AVERAGEIFS(Data!$K$2:$K$5000,Data!$N$2:$N$5000,"OK",Data!$F$2:$F$5000,$B37,Data!$G$2:$G$5000,"<>"),0) -> 2.8932806 | F37: =IFERROR(COUNTIFS(Data!$N$2:$N$5000,"OK",Data!$F$2:$F$5000,$B37,Data!$H$2:$H$5000,"<>")/C37,0) -> 0.20216606 | G37: =IFERROR(COUNTIFS(Data!$N$2:$N$5000,"OK",Data!$F$2:$F$5000,$B37,Data!$J$2:$J$5000,"<>")/C37,0) -> 0.11191336
B38: Counselor C | C38: =COUNTIFS(Data!$N$2:$N$5000,"OK",Data!$F$2:$F$5000,$B38) -> 323 | D38: =IFERROR(AVERAGEIFS(Data!$M$2:$M$5000,Data!$N$2:$N$5000,"OK",Data!$F$2:$F$5000,$B38),0) -> 1.2785235 | E38: =IFERROR(AVERAGEIFS(Data!$K$2:$K$5000,Data!$N$2:$N$5000,"OK",Data!$F$2:$F$5000,$B38,Data!$G$2:$G$5000,"<>"),0) -> 2.8053691 | F38: =IFERROR(COUNTIFS(Data!$N$2:$N$5000,"OK",Data!$F$2:$F$5000,$B38,Data!$H$2:$H$5000,"<>")/C38,0) -> 0.16408669 | G38: =IFERROR(COUNTIFS(Data!$N$2:$N$5000,"OK",Data!$F$2:$F$5000,$B38,Data!$J$2:$J$5000,"<>")/C38,0) -> 0.055727554
B39: Counselor D | C39: =COUNTIFS(Data!$N$2:$N$5000,"OK",Data!$F$2:$F$5000,$B39) -> 246 | D39: =IFERROR(AVERAGEIFS(Data!$M$2:$M$5000,Data!$N$2:$N$5000,"OK",Data!$F$2:$F$5000,$B39),0) -> 2 | E39: =IFERROR(AVERAGEIFS(Data!$K$2:$K$5000,Data!$N$2:$N$5000,"OK",Data!$F$2:$F$5000,$B39,Data!$G$2:$G$5000,"<>"),0) -> 2.8 | F39: =IFERROR(COUNTIFS(Data!$N$2:$N$5000,"OK",Data!$F$2:$F$5000,$B39,Data!$H$2:$H$5000,"<>")/C39,0) -> 0.19918699 | G39: =IFERROR(COUNTIFS(Data!$N$2:$N$5000,"OK",Data!$F$2:$F$5000,$B39,Data!$J$2:$J$5000,"<>")/C39,0) -> 0.089430894
B40: Counselor E | C40: =COUNTIFS(Data!$N$2:$N$5000,"OK",Data!$F$2:$F$5000,$B40) -> 240 | D40: =IFERROR(AVERAGEIFS(Data!$M$2:$M$5000,Data!$N$2:$N$5000,"OK",Data!$F$2:$F$5000,$B40),0) -> 3.0900474 | E40: =IFERROR(AVERAGEIFS(Data!$K$2:$K$5000,Data!$N$2:$N$5000,"OK",Data!$F$2:$F$5000,$B40,Data!$G$2:$G$5000,"<>"),0) -> 2.8862559 | F40: =IFERROR(COUNTIFS(Data!$N$2:$N$5000,"OK",Data!$F$2:$F$5000,$B40,Data!$H$2:$H$5000,"<>")/C40,0) -> 0.17083333 | G40: =IFERROR(COUNTIFS(Data!$N$2:$N$5000,"OK",Data!$F$2:$F$5000,$B40,Data!$J$2:$J$5000,"<>")/C40,0) -> 0.054166667
B41: Counselor F | C41: =COUNTIFS(Data!$N$2:$N$5000,"OK",Data!$F$2:$F$5000,$B41) -> 254 | D41: =IFERROR(AVERAGEIFS(Data!$M$2:$M$5000,Data!$N$2:$N$5000,"OK",Data!$F$2:$F$5000,$B41),0) -> 1.8995633 | E41: =IFERROR(AVERAGEIFS(Data!$K$2:$K$5000,Data!$N$2:$N$5000,"OK",Data!$F$2:$F$5000,$B41,Data!$G$2:$G$5000,"<>"),0) -> 2.6550218 | F41: =IFERROR(COUNTIFS(Data!$N$2:$N$5000,"OK",Data!$F$2:$F$5000,$B41,Data!$H$2:$H$5000,"<>")/C41,0) -> 0.15354331 | G41: =IFERROR(COUNTIFS(Data!$N$2:$N$5000,"OK",Data!$F$2:$F$5000,$B41,Data!$J$2:$J$5000,"<>")/C41,0) -> 0.051181102
B43: 5) SPEED-TO-CONTACT EFFECT
B44: First contact | C44: Leads | D44: Applications | E44: Lead → App % | F44: Enrolled | G44: Lead → Enrolled %
B45: Within 2 days | C45: =COUNTIFS(Data!$N$2:$N$5000,"OK",Data!$M$2:$M$5000,"<=2") -> 1153 | D45: =COUNTIFS(Data!$N$2:$N$5000,"OK",Data!$M$2:$M$5000,"<=2",Data!$H$2:$H$5000,"<>") -> 238 | E45: =IFERROR(D45/C45,0) -> 0.20641804 | F45: =COUNTIFS(Data!$N$2:$N$5000,"OK",Data!$M$2:$M$5000,"<=2",Data!$J$2:$J$5000,"<>") -> 98 | G45: =IFERROR(F45/C45,0) -> 0.084995663
B46: More than 2 days | C46: =COUNTIFS(Data!$N$2:$N$5000,"OK",Data!$M$2:$M$5000,">2") -> 301 | D46: =COUNTIFS(Data!$N$2:$N$5000,"OK",Data!$M$2:$M$5000,">2",Data!$H$2:$H$5000,"<>") -> 46 | E46: =IFERROR(D46/C46,0) -> 0.15282392 | F46: =COUNTIFS(Data!$N$2:$N$5000,"OK",Data!$M$2:$M$5000,">2",Data!$J$2:$J$5000,"<>") -> 19 | G46: =IFERROR(F46/C46,0) -> 0.063122924
...

Sheet Weekly
A1: Week # | B1: Week start (Mon) | C1: Leads | D1: Applications | E1: Enrolled | F1: Forecast: Leads | G1: Forecast: Applications
A2: 1 | B2: 46083 | C2: =COUNTIFS(Data!$N$2:$N$5000,"OK",Data!$B$2:$B$5000,">="&$B2,Data!$B$2:$B$5000,"<"&$B2+7) -> 26 | D2: =COUNTIFS(Data!$N$2:$N$5000,"OK",Data!$H$2:$H$5000,">="&$B2,Data!$H$2:$H$5000,"<"&$B2+7) -> 0 | E2: =COUNTIFS(Data!$N$2:$N$5000,"OK",Data!$J$2:$J$5000,">="&$B2,Data!$J$2:$J$5000,"<"&$B2+7) -> 0
A3: 2 | B3: =B2+7 -> 46090 | C3: =COUNTIFS(Data!$N$2:$N$5000,"OK",Data!$B$2:$B$5000,">="&$B3,Data!$B$2:$B$5000,"<"&$B3+7) -> 25 | D3: =COUNTIFS(Data!$N$2:$N$5000,"OK",Data!$H$2:$H$5000,">="&$B3,Data!$H$2:$H$5000,"<"&$B3+7) -> 0 | E3: =COUNTIFS(Data!$N$2:$N$5000,"OK",Data!$J$2:$J$5000,">="&$B3,Data!$J$2:$J$5000,"<"&$B3+7) -> 0
A4: 3 | B4: =B3+7 -> 46097 | C4: =COUNTIFS(Data!$N$2:$N$5000,"OK",Data!$B$2:$B$5000,">="&$B4,Data!$B$2:$B$5000,"<"&$B4+7) -> 26 | D4: =COUNTIFS(Data!$N$2:$N$5000,"OK",Data!$H$2:$H$5000,">="&$B4,Data!$H$2:$H$5000,"<"&$B4+7) -> 2 | E4: =COUNTIFS(Data!$N$2:$N$5000,"OK",Data!$J$2:$J$5000,">="&$B4,Data!$J$2:$J$5000,"<"&$B4+7) -> 0
A5: 4 | B5: =B4+7 -> 46104 | C5: =COUNTIFS(Data!$N$2:$N$5000,"OK",Data!$B$2:$B$5000,">="&$B5,Data!$B$2:$B$5000,"<"&$B5+7) -> 36 | D5: =COUNTIFS(Data!$N$2:$N$5000,"OK",Data!$H$2:$H$5000,">="&$B5,Data!$H$2:$H$5000,"<"&$B5+7) -> 2 | E5: =COUNTIFS(Data!$N$2:$N$5000,"OK",Data!$J$2:$J$5000,">="&$B5,Data!$J$2:$J$5000,"<"&$B5+7) -> 0
A6: 5 | B6: =B5+7 -> 46111 | C6: =COUNTIFS(Data!$N$2:$N$5000,"OK",Data!$B$2:$B$5000,">="&$B6,Data!$B$2:$B$5000,"<"&$B6+7) -> 47 | D6: =COUNTIFS(Data!$N$2:$N$5000,"OK",Data!$H$2:$H$5000,">="&$B6,Data!$H$2:$H$5000,"<"&$B6+7) -> 5 | E6: =COUNTIFS(Data!$N$2:$N$5000,"OK",Data!$J$2:$J$5000,">="&$B6,Data!$J$2:$J$5000,"<"&$B6+7) -> 0
A7: 6 | B7: =B6+7 -> 46118 | C7: =COUNTIFS(Data!$N$2:$N$5000,"OK",Data!$B$2:$B$5000,">="&$B7,Data!$B$2:$B$5000,"<"&$B7+7) -> 49 | D7: =COUNTIFS(Data!$N$2:$N$5000,"OK",Data!$H$2:$H$5000,">="&$B7,Data!$H$2:$H$5000,"<"&$B7+7) -> 7 | E7: =COUNTIFS(Data!$N$2:$N$5000,"OK",Data!$J$2:$J$5000,">="&$B7,Data!$J$2:$J$5000,"<"&$B7+7) -> 0
A8: 7 | B8: =B7+7 -> 46125 | C8: =COUNTIFS(Data!$N$2:$N$5000,"OK",Data!$B$2:$B$5000,">="&$B8,Data!$B$2:$B$5000,"<"&$B8+7) -> 49 | D8: =COUNTIFS(Data!$N$2:$N$5000,"OK",Data!$H$2:$H$5000,">="&$B8,Data!$H$2:$H$5000,"<"&$B8+7) -> 11 | E8: =COUNTIFS(Data!$N$2:$N$5000,"OK",Data!$J$2:$J$5000,">="&$B8,Data!$J$2:$J$5000,"<"&$B8+7) -> 0
A9: 8 | B9: =B8+7 -> 46132 | C9: =COUNTIFS(Data!$N$2:$N$5000,"OK",Data!$B$2:$B$5000,">="&$B9,Data!$B$2:$B$5000,"<"&$B9+7) -> 36 | D9: =COUNTIFS(Data!$N$2:$N$5000,"OK",Data!$H$2:$H$5000,">="&$B9,Data!$H$2:$H$5000,"<"&$B9+7) -> 9 | E9: =COUNTIFS(Data!$N$2:$N$5000,"OK",Data!$J$2:$J$5000,">="&$B9,Data!$J$2:$J$5000,"<"&$B9+7) -> 1
A10: 9 | B10: =B9+7 -> 46139 | C10: =COUNTIFS(Data!$N$2:$N$5000,"OK",Data!$B$2:$B$5000,">="&$B10,Data!$B$2:$B$5000,"<"&$B10+7) -> 61 | D10: =COUNTIFS(Data!$N$2:$N$5000,"OK",Data!$H$2:$H$5000,">="&$B10,Data!$H$2:$H$5000,"<"&$B10+7) -> 8 | E10: =COUNTIFS(Data!$N$2:$N$5000,"OK",Data!$J$2:$J$5000,">="&$B10,Data!$J$2:$J$5000,"<"&$B10+7) -> 2
A11: 10 | B11: =B10+7 -> 46146 | C11: =COUNTIFS(Data!$N$2:$N$5000,"OK",Data!$B$2:$B$5000,">="&$B11,Data!$B$2:$B$5000,"<"&$B11+7) -> 37 | D11: =COUNTIFS(Data!$N$2:$N$5000,"OK",Data!$H$2:$H$5000,">="&$B11,Data!$H$2:$H$5000,"<"&$B11+7) -> 5 | E11: =COUNTIFS(Data!$N$2:$N$5000,"OK",Data!$J$2:$J$5000,">="&$B11,Data!$J$2:$J$5000,"<"&$B11+7) -> 4
A12: 11 | B12: =B11+7 -> 46153 | C12: =COUNTIFS(Data!$N$2:$N$5000,"OK",Data!$B$2:$B$5000,">="&$B12,Data!$B$2:$B$5000,"<"&$B12+7) -> 52 | D12: =COUNTIFS(Data!$N$2:$N$5000,"OK",Data!$H$2:$H$5000,">="&$B12,Data!$H$2:$H$5000,"<"&$B12+7) -> 7 | E12: =COUNTIFS(Data!$N$2:$N$5000,"OK",Data!$J$2:$J$5000,">="&$B12,Data!$J$2:$J$5000,"<"&$B12+7) -> 7
A13: 12 | B13: =B12+7 -> 46160 | C13: =COUNTIFS(Data!$N$2:$N$5000,"OK",Data!$B$2:$B$5000,">="&$B13,Data!$B$2:$B$5000,"<"&$B13+7) -> 60 | D13: =COUNTIFS(Data!$N$2:$N$5000,"OK",Data!$H$2:$H$5000,">="&$B13,Data!$H$2:$H$5000,"<"&$B13+7) -> 10 | E13: =COUNTIFS(Data!$N$2:$N$5000,"OK",Data!$J$2:$J$5000,">="&$B13,Data!$J$2:$J$5000,"<"&$B13+7) -> 5
A14: 13 | B14: =B13+7 -> 46167 | C14: =COUNTIFS(Data!$N$2:$N$5000,"OK",Data!$B$2:$B$5000,">="&$B14,Data!$B$2:$B$5000,"<"&$B14+7) -> 55 | D14: =COUNTIFS(Data!$N$2:$N$5000,"OK",Data!$H$2:$H$5000,">="&$B14,Data!$H$2:$H$5000,"<"&$B14+7) -> 14 | E14: =COUNTIFS(Data!$N$2:$N$5000,"OK",Data!$J$2:$J$5000,">="&$B14,Data!$J$2:$J$5000,"<"&$B14+7) -> 4
... A26: 25 | B26: =B25+7 -> 46251 | C26: =COUNTIFS(Data!$N$2:$N$5000,"OK",Data!$B$2:$B$5000,">="&$B26,Data!$B$2:$B$5000,"<"&$B26+7) -> 98 | D26: =COUNTIFS(Data!$N$2:$N$5000,"OK",Data!$H$2:$H$5000,">="&$B26,Data!$H$2:$H$5000,"<"&$B26+7) -> 18 | E26: =COUNTIFS(Data!$N$2:$N$5000,"OK",Data!$J$2:$J$5000,">="&$B26,Data!$J$2:$J$5000,"<"&$B26+7) -> 10
A27: 26 | B27: =B26+7 -> 46258 | C27: =COUNTIFS(Data!$N$2:$N$5000,"OK",Data!$B$2:$B$5000,">="&$B27,Data!$B$2:$B$5000,"<"&$B27+7) -> 85 | D27: =COUNTIFS(Data!$N$2:$N$5000,"OK",Data!$H$2:$H$5000,">="&$B27,Data!$H$2:$H$5000,"<"&$B27+7) -> 17 | E27: =COUNTIFS(Data!$N$2:$N$5000,"OK",Data!$J$2:$J$5000,">="&$B27,Data!$J$2:$J$5000,"<"&$B27+7) -> 8 | F27: =C27 -> 85 | G27: =D27 -> 17
A28: 27 | B28: =B27+7 -> 46265 | F28: =ROUND(FORECAST($A28,$C$2:$C$27,$A$2:$A$27),0) -> 98 | G28: =ROUND(FORECAST($A28,$D$2:$D$27,$A$2:$A$27),0) -> 21
A29: 28 | B29: =B28+7 -> 46272 | F29: =ROUND(FORECAST($A29,$C$2:$C$27,$A$2:$A$27),0) -> 101 | G29: =ROUND(FORECAST($A29,$D$2:$D$27,$A$2:$A$27),0) -> 21
A30: 29 | B30: =B29+7 -> 46279 | F30: =ROUND(FORECAST($A30,$C$2:$C$27,$A$2:$A$27),0) -> 103 | G30: =ROUND(FORECAST($A30,$D$2:$D$27,$A$2:$A$27),0) -> 22
A31: 30 | B31: =B30+7 -> 46286 | F31: =ROUND(FORECAST($A31,$C$2:$C$27,$A$2:$A$27),0) -> 106 | G31: =ROUND(FORECAST($A31,$D$2:$D$27,$A$2:$A$27),0) -> 23
A34: Notes
A35: Blue = the one hardcoded input (first week start). All other cells are formulas on the Data sheet (valid records only).
A36: Leads counted by created_date; Applications by application_date; Enrolled by enroll_date, all within the Mon-Sun week.
A37: Forecast (grey rows) = naive linear trend (FORECAST) over the 26 weeks above. Illustrative only: it does not model seasonality or campaign calendars.
A38: The first forecast-column cell on the last actual week repeats the actual value so the chart line joins up.

Sheet Monthly
A1: Lead cohort (month created) | B1: Leads | C1: Contacted | D1: Applied | E1: Admitted | F1: Enrolled | G1: Lead → App % | H1: Lead → Enrolled %
A2: 46082 | B2: =COUNTIFS(Data!$N$2:$N$5000,"OK",Data!$B$2:$B$5000,">="&$A2,Data!$B$2:$B$5000,"<"&EDATE($A2,1)) -> 123 | C2: =COUNTIFS(Data!$N$2:$N$5000,"OK",Data!$B$2:$B$5000,">="&$A2,Data!$B$2:$B$5000,"<"&EDATE($A2,1),Data!$G$2:$G$5000,"<>") -> 111 | D2: =COUNTIFS(Data!$N$2:$N$5000,"OK",Data!$B$2:$B$5000,">="&$A2,Data!$B$2:$B$5000,"<"&EDATE($A2,1),Data!$H$2:$H$5000,"<>") -> 19 | E2: =COUNTIFS(Data!$N$2:$N$5000,"OK",Data!$B$2:$B$5000,">="&$A2,Data!$B$2:$B$5000,"<"&EDATE($A2,1),Data!$I$2:$I$5000,"<>") -> 15 | F2: =COUNTIFS(Data!$N$2:$N$5000,"OK",Data!$B$2:$B$5000,">="&$A2,Data!$B$2:$B$5000,"<"&EDATE($A2,1),Data!$J$2:$J$5000,"<>") -> 10 | G2: =IFERROR(D2/B2,0) -> 0.15447154 | H2: =IFERROR(F2/B2,0) -> 0.081300813
A3: =EDATE(A2,1) -> 46113 | B3: =COUNTIFS(Data!$N$2:$N$5000,"OK",Data!$B$2:$B$5000,">="&$A3,Data!$B$2:$B$5000,"<"&EDATE($A3,1)) -> 203 | C3: =COUNTIFS(Data!$N$2:$N$5000,"OK",Data!$B$2:$B$5000,">="&$A3,Data!$B$2:$B$5000,"<"&EDATE($A3,1),Data!$G$2:$G$5000,"<>") -> 186 | D3: =COUNTIFS(Data!$N$2:$N$5000,"OK",Data!$B$2:$B$5000,">="&$A3,Data!$B$2:$B$5000,"<"&EDATE($A3,1),Data!$H$2:$H$5000,"<>") -> 38 | E3: =COUNTIFS(Data!$N$2:$N$5000,"OK",Data!$B$2:$B$5000,">="&$A3,Data!$B$2:$B$5000,"<"&EDATE($A3,1),Data!$I$2:$I$5000,"<>") -> 34 | F3: =COUNTIFS(Data!$N$2:$N$5000,"OK",Data!$B$2:$B$5000,">="&$A3,Data!$B$2:$B$5000,"<"&EDATE($A3,1),Data!$J$2:$J$5000,"<>") -> 24 | G3: =IFERROR(D3/B3,0) -> 0.18719212 | H3: =IFERROR(F3/B3,0) -> 0.1182266
A4: =EDATE(A3,1) -> 46143 | B4: =COUNTIFS(Data!$N$2:$N$5000,"OK",Data!$B$2:$B$5000,">="&$A4,Data!$B$2:$B$5000,"<"&EDATE($A4,1)) -> 233 | C4: =COUNTIFS(Data!$N$2:$N$5000,"OK",Data!$B$2:$B$5000,">="&$A4,Data!$B$2:$B$5000,"<"&EDATE($A4,1),Data!$G$2:$G$5000,"<>") -> 217 | D4: =COUNTIFS(Data!$N$2:$N$5000,"OK",Data!$B$2:$B$5000,">="&$A4,Data!$B$2:$B$5000,"<"&EDATE($A4,1),Data!$H$2:$H$5000,"<>") -> 52 | E4: =COUNTIFS(Data!$N$2:$N$5000,"OK",Data!$B$2:$B$5000,">="&$A4,Data!$B$2:$B$5000,"<"&EDATE($A4,1),Data!$I$2:$I$5000,"<>") -> 45 | F4: =COUNTIFS(Data!$N$2:$N$5000,"OK",Data!$B$2:$B$5000,">="&$A4,Data!$B$2:$B$5000,"<"&EDATE($A4,1),Data!$J$2:$J$5000,"<>") -> 29 | G4: =IFERROR(D4/B4,0) -> 0.22317597 | H4: =IFERROR(F4/B4,0) -> 0.12446352
A5: =EDATE(A4,1) -> 46174 | B5: =COUNTIFS(Data!$N$2:$N$5000,"OK",Data!$B$2:$B$5000,">="&$A5,Data!$B$2:$B$5000,"<"&EDATE($A5,1)) -> 298 | C5: =COUNTIFS(Data!$N$2:$N$5000,"OK",Data!$B$2:$B$5000,">="&$A5,Data!$B$2:$B$5000,"<"&EDATE($A5,1),Data!$G$2:$G$5000,"<>") -> 274 | D5: =COUNTIFS(Data!$N$2:$N$5000,"OK",Data!$B$2:$B$5000,">="&$A5,Data!$B$2:$B$5000,"<"&EDATE($A5,1),Data!$H$2:$H$5000,"<>") -> 63 | E5: =COUNTIFS(Data!$N$2:$N$5000,"OK",Data!$B$2:$B$5000,">="&$A5,Data!$B$2:$B$5000,"<"&EDATE($A5,1),Data!$I$2:$I$5000,"<>") -> 53 | F5: =COUNTIFS(Data!$N$2:$N$5000,"OK",Data!$B$2:$B$5000,">="&$A5,Data!$B$2:$B$5000,"<"&EDATE($A5,1),Data!$J$2:$J$5000,"<>") -> 35 | G5: =IFERROR(D5/B5,0) -> 0.2114094 | H5: =IFERROR(F5/B5,0) -> 0.11744966
A6: =EDATE(A5,1) -> 46204 | B6: =COUNTIFS(Data!$N$2:$N$5000,"OK",Data!$B$2:$B$5000,">="&$A6,Data!$B$2:$B$5000,"<"&EDATE($A6,1)) -> 360 | C6: =COUNTIFS(Data!$N$2:$N$5000,"OK",Data!$B$2:$B$5000,">="&$A6,Data!$B$2:$B$5000,"<"&EDATE($A6,1),Data!$G$2:$G$5000,"<>") -> 336 | D6: =COUNTIFS(Data!$N$2:$N$5000,"OK",Data!$B$2:$B$5000,">="&$A6,Data!$B$2:$B$5000,"<"&EDATE($A6,1),Data!$H$2:$H$5000,"<>") -> 80 | E6: =COUNTIFS(Data!$N$2:$N$5000,"OK",Data!$B$2:$B$5000,">="&$A6,Data!$B$2:$B$5000,"<"&EDATE($A6,1),Data!$I$2:$I$5000,"<>") -> 61 | F6: =COUNTIFS(Data!$N$2:$N$5000,"OK",Data!$B$2:$B$5000,">="&$A6,Data!$B$2:$B$5000,"<"&EDATE($A6,1),Data!$J$2:$J$5000,"<>") -> 19 | G6: =IFERROR(D6/B6,0) -> 0.22222222 | H6: =IFERROR(F6/B6,0) -> 0.052777778
A7: =EDATE(A6,1) -> 46235 | B7: =COUNTIFS(Data!$N$2:$N$5000,"OK",Data!$B$2:$B$5000,">="&$A7,Data!$B$2:$B$5000,"<"&EDATE($A7,1)) -> 376 | C7: =COUNTIFS(Data!$N$2:$N$5000,"OK",Data!$B$2:$B$5000,">="&$A7,Data!$B$2:$B$5000,"<"&EDATE($A7,1),Data!$G$2:$G$5000,"<>") -> 330 | D7: =COUNTIFS(Data!$N$2:$N$5000,"OK",Data!$B$2:$B$5000,">="&$A7,Data!$B$2:$B$5000,"<"&EDATE($A7,1),Data!$H$2:$H$5000,"<>") -> 32 | E7: =COUNTIFS(Data!$N$2:$N$5000,"OK",Data!$B$2:$B$5000,">="&$A7,Data!$B$2:$B$5000,"<"&EDATE($A7,1),Data!$I$2:$I$5000,"<>") -> 9 | F7: =COUNTIFS(Data!$N$2:$N$5000,"OK",Data!$B$2:$B$5000,">="&$A7,Data!$B$2:$B$5000,"<"&EDATE($A7,1),Data!$J$2:$J$5000,"<>") -> 0 | G7: =IFERROR(D7/B7,0) -> 0.085106383 | H7: =IFERROR(F7/B7,0) -> 0
A8: Total | B8: =SUM(B2:B7) -> 1593 | C8: =SUM(C2:C7) -> 1454 | D8: =SUM(D2:D7) -> 284 | E8: =SUM(E2:E7) -> 217 | F8: =SUM(F2:F7) -> 117 | G8: =IFERROR(D8/B8,0) -> 0.17827997 | H8: =IFERROR(F8/B8,0) -> 0.073446328
A10: Cohort view: each row follows the leads created in that month. Later cohorts look weaker because their applications/enrolments are still pending at the 30-Aug-2026 snapshot, not because quality dropped.
A11: Blue = hardcoded input (first month). Everything else is a formula on the Data sheet (valid records only).

Sheet Data
A1: lead_id | B1: created_date | C1: source | D1: program | E1: school_type | F1: counselor | G1: first_contact_date | H1: application_date | I1: admit_date | J1: enroll_date | K1: follow_ups | L1: stage | M1: days_to_first_contact | N1: dq_flag
A2: L1059 | B2: 46083 | C2: Google Ads | D2: Business Administration | E2: IGCSE | F2: Counselor C | G2: 46083 | K2: 6 | L2: =IF(J2<>"","Enrolled",IF(I2<>"","Admitted",IF(H2<>"","Applied",IF(G2<>"","Contacted","New")))) -> Contacted | M2: =IF(G2="","",G2-B2) -> 0 | N2: =IF(COUNTIF($A$2:A2,A2)>1,"Duplicate ID",IF(C2="","Missing source",IF(OR(AND(G2<>"",G2<B2),AND(H2<>"",H2<B2),AND(I2<>"",I2<H2),AND(J2<>"",J2<I2)),"Date error","OK"))) -> OK
A3: L1469 | B3: 46083 | C3: Meta Ads | D3: Computer Science | E3: Azhar/Other | F3: Counselor C | G3: 46084 | K3: 1 | L3: =IF(J3<>"","Enrolled",IF(I3<>"","Admitted",IF(H3<>"","Applied",IF(G3<>"","Contacted","New")))) -> Contacted | M3: =IF(G3="","",G3-B3) -> 1 | N3: =IF(COUNTIF($A$2:A3,A3)>1,"Duplicate ID",IF(C3="","Missing source",IF(OR(AND(G3<>"",G3<B3),AND(H3<>"",H3<B3),AND(I3<>"",I3<H3),AND(J3<>"",J3<I3)),"Date error","OK"))) -> OK
A4: L1487 | B4: 46083 | C4: Referral | D4: Business Administration | E4: IGCSE | F4: Counselor A | G4: 46083 | K4: 5 | L4: =IF(J4<>"","Enrolled",IF(I4<>"","Admitted",IF(H4<>"","Applied",IF(G4<>"","Contacted","New")))) -> Contacted | M4: =IF(G4="","",G4-B4) -> 0 | N4: =IF(COUNTIF($A$2:A4,A4)>1,"Duplicate ID",IF(C4="","Missing source",IF(OR(AND(G4<>"",G4<B4),AND(H4<>"",H4<B4),AND(I4<>"",I4<H4),AND(J4<>"",J4<I4)),"Date error","OK"))) -> OK
A5: L1944 | B5: 46083 | C5: Google Ads | D5: Computer Science | E5: IB | F5: Counselor C | G5: 46085 | K5: 3 | L5: =IF(J5<>"","Enrolled",IF(I5<>"","Admitted",IF(H5<>"","Applied",IF(G5<>"","Contacted","New")))) -> Contacted | M5: =IF(G5="","",G5-B5) -> 2 | N5: =IF(COUNTIF($A$2:A5,A5)>1,"Duplicate ID",IF(C5="","Missing source",IF(OR(AND(G5<>"",G5<B5),AND(H5<>"",H5<B5),AND(I5<>"",I5<H5),AND(J5<>"",J5<I5)),"Date error","OK"))) -> OK
A6: L2482 | B6: 46083 | C6: Meta Ads | D6: Business Administration | E6: IB | F6: Counselor F | G6: 46085 | K6: 3 | L6: =IF(J6<>"","Enrolled",IF(I6<>"","Admitted",IF(H6<>"","Applied",IF(G6<>"","Contacted","New")))) -> Contacted | M6: =IF(G6="","",G6-B6) -> 2 | N6: =IF(COUNTIF($A$2:A6,A6)>1,"Duplicate ID",IF(C6="","Missing source",IF(OR(AND(G6<>"",G6<B6),AND(H6<>"",H6<B6),AND(I6<>"",I6<H6),AND(J6<>"",J6<I6)),"Date error","OK"))) -> OK
A7: L1734 | B7: 46084 | C7: Website Organic | D7: Business Administration | E7: IB | F7: Counselor A | G7: 46084 | K7: 4 | L7: =IF(J7<>"","Enrolled",IF(I7<>"","Admitted",IF(H7<>"","Applied",IF(G7<>"","Contacted","New")))) -> Contacted | M7: =IF(G7="","",G7-B7) -> 0 | N7: =IF(COUNTIF($A$2:A7,A7)>1,"Duplicate ID",IF(C7="","Missing source",IF(OR(AND(G7<>"",G7<B7),AND(H7<>"",H7<B7),AND(I7<>"",I7<H7),AND(J7<>"",J7<I7)),"Date error","OK"))) -> OK
A8: L2010 | B8: 46084 | C8: Meta Ads | D8: Business Administration | E8: IGCSE | F8: Counselor F | K8: 0 | L8: =IF(J8<>"","Enrolled",IF(I8<>"","Admitted",IF(H8<>"","Applied",IF(G8<>"","Contacted","New")))) -> New | M8: =IF(G8="","",G8-B8) | N8: =IF(COUNTIF($A$2:A8,A8)>1,"Duplicate ID",IF(C8="","Missing source",IF(OR(AND(G8<>"",G8<B8),AND(H8<>"",H8<B8),AND(I8<>"",I8<H8),AND(J8<>"",J8<I8)),"Date error","OK"))) -> OK
A9: L2164 | B9: 46084 | C9: School Visit | D9: Computer Science | E9: National (Thanaweya Amma) | F9: Counselor C | G9: 46084 | K9: 3 | L9: =IF(J9<>"","Enrolled",IF(I9<>"","Admitted",IF(H9<>"","Applied",IF(G9<>"","Contacted","New")))) -> Contacted | M9: =IF(G9="","",G9-B9) -> 0 | N9: =IF(COUNTIF($A$2:A9,A9)>1,"Duplicate ID",IF(C9="","Missing source",IF(OR(AND(G9<>"",G9<B9),AND(H9<>"",H9<B9),AND(I9<>"",I9<H9),AND(J9<>"",J9<I9)),"Date error","OK"))) -> OK
A10: L2207 | B10: 46084 | C10: Website Organic | D10: Engineering | E10: National (Thanaweya Amma) | F10: Counselor A | G10: 46084 | K10: 4 | L10: =IF(J10<>"","Enrolled",IF(I10<>"","Admitted",IF(H10<>"","Applied",IF(G10<>"","Contacted","New")))) -> Contacted | M10: =IF(G10="","",G10-B10) -> 0 | N10: =IF(COUNTIF($A$2:A10,A10)>1,"Duplicate ID",IF(C10="","Missing source",IF(OR(AND(G10<>"",G10<B10),AND(H10<>"",H10<B10),AND(I10<>"",I10<H10),AND(J10<>"",J10<I10)),"Date error","OK"))) -> OK
A11: L2570 | B11: 46084 | C11: School Visit | D11: Business Administration | E11: National (Thanaweya Amma) | F11: Counselor B | G11: 46084 | K11: 5 | L11: =IF(J11<>"","Enrolled",IF(I11<>"","Admitted",IF(H11<>"","Applied",IF(G11<>"","Contacted","New")))) -> Contacted | M11: =IF(G11="","",G11-B11) -> 0 | N11: =IF(COUNTIF($A$2:A11,A11)>1,"Duplicate ID",IF(C11="","Missing source",IF(OR(AND(G11<>"",G11<B11),AND(H11<>"",H11<B11),AND(I11<>"",I11<H11),AND(J11<>"",J11<I11)),"Date error","OK"))) -> OK
A12: L1421 | B12: 46085 | C12: Walk-in | D12: Engineering | E12: IGCSE | F12: Counselor C | G12: 46085 | K12: 7 | L12: =IF(J12<>"","Enrolled",IF(I12<>"","Admitted",IF(H12<>"","Applied",IF(G12<>"","Contacted","New")))) -> Contacted | M12: =IF(G12="","",G12-B12) -> 0 | N12: =IF(COUNTIF($A$2:A12,A12)>1,"Duplicate ID",IF(C12="","Missing source",IF(OR(AND(G12<>"",G12<B12),AND(H12<>"",H12<B12),AND(I12<>"",I12<H12),AND(J12<>"",J12<I12)),"Date error","OK"))) -> OK
A13: L2071 | B13: 46085 | C13: Referral | D13: Computer Science | E13: American Diploma | F13: Counselor E | G13: 46099 | K13: 5 | L13: =IF(J13<>"","Enrolled",IF(I13<>"","Admitted",IF(H13<>"","Applied",IF(G13<>"","Contacted","New")))) -> Contacted | M13: =IF(G13="","",G13-B13) -> 14 | N13: =IF(COUNTIF($A$2:A13,A13)>1,"Duplicate ID",IF(C13="","Missing source",IF(OR(AND(G13<>"",G13<B13),AND(H13<>"",H13<B13),AND(I13<>"",I13<H13),AND(J13<>"",J13<I13)),"Date error","OK"))) -> OK
A14: L1277 | B14: 46086 | C14: Google Ads | D14: Engineering | E14: IGCSE | F14: Counselor E | K14: 0 | L14: =IF(J14<>"","Enrolled",IF(I14<>"","Admitted",IF(H14<>"","Applied",IF(G14<>"","Contacted","New")))) -> New | M14: =IF(G14="","",G14-B14) | N14: =IF(COUNTIF($A$2:A14,A14)>1,"Duplicate ID",IF(C14="","Missing source",IF(OR(AND(G14<>"",G14<B14),AND(H14<>"",H14<B14),AND(I14<>"",I14<H14),AND(J14<>"",J14<I14)),"Date error","OK"))) -> OK
A15: L1676 | B15: 46086 | C15: Google Ads | D15: Engineering | E15: National (Thanaweya Amma) | F15: Counselor A | G15: 46087 | K15: 2 | L15: =IF(J15<>"","Enrolled",IF(I15<>"","Admitted",IF(H15<>"","Applied",IF(G15<>"","Contacted","New")))) -> Contacted | M15: =IF(G15="","",G15-B15) -> 1 | N15: =IF(COUNTIF($A$2:A15,A15)>1,"Duplicate ID",IF(C15="","Missing source",IF(OR(AND(G15<>"",G15<B15),AND(H15<>"",H15<B15),AND(I15<>"",I15<H15),AND(J15<>"",J15<I15)),"Date error","OK"))) -> OK
A16: L1815 | B16: 46086 | C16: Meta Ads | D16: Mass Communication | E16: IGCSE | F16: Counselor D | G16: 46089 | K16: 3 | L16: =IF(J16<>"","Enrolled",IF(I16<>"","Admitted",IF(H16<>"","Applied",IF(G16<>"","Contacted","New")))) -> Contacted | M16: =IF(G16="","",G16-B16) -> 3 | N16: =IF(COUNTIF($A$2:A16,A16)>1,"Duplicate ID",IF(C16="","Missing source",IF(OR(AND(G16<>"",G16<B16),AND(H16<>"",H16<B16),AND(I16<>"",I16<H16),AND(J16<>"",J16<I16)),"Date error","OK"))) -> OK
A17: L1877 | B17: 46086 | C17: School Visit | D17: Engineering | E17: National (Thanaweya Amma) | F17: Counselor C | G17: 46087 | K17: 1 | L17: =IF(J17<>"","Enrolled",IF(I17<>"","Admitted",IF(H17<>"","Applied",IF(G17<>"","Contacted","New")))) -> Contacted | M17: =IF(G17="","",G17-B17) -> 1 | N17: =IF(COUNTIF($A$2:A17,A17)>1,"Duplicate ID",IF(C17="","Missing source",IF(OR(AND(G17<>"",G17<B17),AND(H17<>"",H17<B17),AND(I17<>"",I17<H17),AND(J17<>"",J17<I17)),"Date error","OK"))) -> OK
A18: L2078 | B18: 46086 | C18: Website Organic | D18: Health Sciences | E18: National (Thanaweya Amma) | F18: Counselor C | G18: 46087 | K18: 6 | L18: =IF(J18<>"","Enrolled",IF(I18<>"","Admitted",IF(H18<>"","Applied",IF(G18<>"","Contacted","New")))) -> Contacted | M18: =IF(G18="","",G18-B18) -> 1 | N18: =IF(COUNTIF($A$2:A18,A18)>1,"Duplicate ID",IF(C18="","Missing source",IF(OR(AND(G18<>"",G18<B18),AND(H18<>"",H18<B18),AND(I18<>"",I18<H18),AND(J18<>"",J18<I18)),"Date error","OK"))) -> OK
A19: L1024 | B19: 46087 | C19: Referral | D19: Mass Communication | E19: IB | F19: Counselor E | G19: 46095 | K19: 4 | L19: =IF(J19<>"","Enrolled",IF(I19<>"","Admitted",IF(H19<>"","Applied",IF(G19<>"","Contacted","New")))) -> Contacted | M19: =IF(G19="","",G19-B19) -> 8 | N19: =IF(COUNTIF($A$2:A19,A19)>1,"Duplicate ID",IF(C19="","Missing source",IF(OR(AND(G19<>"",G19<B19),AND(H19<>"",H19<B19),AND(I19<>"",I19<H19),AND(J19<>"",J19<I19)),"Date error","OK"))) -> OK
A20: L1085 | B20: 46087 | C20: Meta Ads | D20: Engineering | E20: American Diploma | F20: Counselor B | G20: 46090 | K20: 1 | L20: =IF(J20<>"","Enrolled",IF(I20<>"","Admitted",IF(H20<>"","Applied",IF(G20<>"","Contacted","New")))) -> Contacted | M20: =IF(G20="","",G20-B20) -> 3 | N20: =IF(COUNTIF($A$2:A20,A20)>1,"Duplicate ID",IF(C20="","Missing source",IF(OR(AND(G20<>"",G20<B20),AND(H20<>"",H20<B20),AND(I20<>"",I20<H20),AND(J20<>"",J20<I20)),"Date error","OK"))) -> OK
A21: L1838 | B21: 46087 | C21: Meta Ads | D21: Computer Science | E21: National (Thanaweya Amma) | F21: Counselor B | G21: 46088 | K21: 4 | L21: =IF(J21<>"","Enrolled",IF(I21<>"","Admitted",IF(H21<>"","Applied",IF(G21<>"","Contacted","New")))) -> Contacted | M21: =IF(G21="","",G21-B21) -> 1 | N21: =IF(COUNTIF($A$2:A21,A21)>1,"Duplicate ID",IF(C21="","Missing source",IF(OR(AND(G21<>"",G21<B21),AND(H21<>"",H21<B21),AND(I21<>"",I21<H21),AND(J21<>"",J21<I21)),"Date error","OK"))) -> OK
A22: L1231 | B22: 46088 | C22: School Visit | D22: Computer Science | E22: IGCSE | F22: Counselor F | G22: 46089 | H22: 46109 | I22: 46122 | K22: 1 | L22: =IF(J22<>"","Enrolled",IF(I22<>"","Admitted",IF(H22<>"","Applied",IF(G22<>"","Contacted","New")))) -> Admitted | M22: =IF(G22="","",G22-B22) -> 1 | N22: =IF(COUNTIF($A$2:A22,A22)>1,"Duplicate ID",IF(C22="","Missing source",IF(OR(AND(G22<>"",G22<B22),AND(H22<>"",H22<B22),AND(I22<>"",I22<H22),AND(J22<>"",J22<I22)),"Date error","OK"))) -> OK
A23: L1268 | B23: 46088 | C23: Walk-in | D23: Health Sciences | E23: IGCSE | F23: Counselor E | G23: 46097 | H23: 46121 | K23: 3 | L23: =IF(J23<>"","Enrolled",IF(I23<>"","Admitted",IF(H23<>"","Applied",IF(G23<>"","Contacted","New")))) -> Applied | M23: =IF(G23="","",G23-B23) -> 9 | N23: =IF(COUNTIF($A$2:A23,A23)>1,"Duplicate ID",IF(C23="","Missing source",IF(OR(AND(G23<>"",G23<B23),AND(H23<>"",H23<B23),AND(I23<>"",I23<H23),AND(J23<>"",J23<I23)),"Date error","OK"))) -> OK
A24: L1303 | B24: 46089 | C24: Meta Ads | D24: Engineering | E24: Azhar/Other | F24: Counselor A | G24: 46089 | K24: 2 | L24: =IF(J24<>"","Enrolled",IF(I24<>"","Admitted",IF(H24<>"","Applied",IF(G24<>"","Contacted","New")))) -> Contacted | M24: =IF(G24="","",G24-B24) -> 0 | N24: =IF(COUNTIF($A$2:A24,A24)>1,"Duplicate ID",IF(C24="","Missing source",IF(OR(AND(G24<>"",G24<B24),AND(H24<>"",H24<B24),AND(I24<>"",I24<H24),AND(J24<>"",J24<I24)),"Date error","OK"))) -> OK
A25: L1713 | B25: 46089 | C25: Walk-in | D25: Business Administration | E25: National (Thanaweya Amma) | F25: Counselor D | G25: 46089 | H25: 46107 | K25: 3 | L25: =IF(J25<>"","Enrolled",IF(I25<>"","Admitted",IF(H25<>"","Applied",IF(G25<>"","Contacted","New")))) -> Applied | M25: =IF(G25="","",G25-B25) -> 0 | N25: =IF(COUNTIF($A$2:A25,A25)>1,"Duplicate ID",IF(C25="","Missing source",IF(OR(AND(G25<>"",G25<B25),AND(H25<>"",H25<B25),AND(I25<>"",I25<H25),AND(J25<>"",J25<I25)),"Date error","OK"))) -> OK
A26: L2018 | B26: 46089 | C26: Meta Ads | D26: Business Administration | E26: National (Thanaweya Amma) | F26: Counselor C | G26: 46090 | K26: 5 | L26: =IF(J26<>"","Enrolled",IF(I26<>"","Admitted",IF(H26<>"","Applied",IF(G26<>"","Contacted","New")))) -> Contacted | M26: =IF(G26="","",G26-B26) -> 1 | N26: =IF(COUNTIF($A$2:A26,A26)>1,"Duplicate ID",IF(C26="","Missing source",IF(OR(AND(G26<>"",G26<B26),AND(H26<>"",H26<B26),AND(I26<>"",I26<H26),AND(J26<>"",J26<I26)),"Date error","OK"))) -> OK
A27: L2339 | B27: 46089 | C27: Google Ads | D27: Engineering | E27: Azhar/Other | F27: Counselor C | G27: 46091 | K27: 3 | L27: =IF(J27<>"","Enrolled",IF(I27<>"","Admitted",IF(H27<>"","Applied",IF(G27<>"","Contacted","New")))) -> Contacted | M27: =IF(G27="","",G27-B27) -> 2 | N27: =IF(COUNTIF($A$2:A27,A27)>1,"Duplicate ID",IF(C27="","Missing source",IF(OR(AND(G27<>"",G27<B27),AND(H27<>"",H27<B27),AND(I27<>"",I27<H27),AND(J27<>"",J27<I27)),"Date error","OK"))) -> OK
A28: L1945 | B28: 46090 | C28: Education Fair | D28: Health Sciences | E28: IGCSE | F28: Counselor B | G28: 46090 | K28: 1 | L28: =IF(J28<>"","Enrolled",IF(I28<>"","Admitted",IF(H28<>"","Applied",IF(G28<>"","Contacted","New")))) -> Contacted | M28: =IF(G28="","",G28-B28) -> 0 | N28: =IF(COUNTIF($A$2:A28,A28)>1,"Duplicate ID",IF(C28="","Missing source",IF(OR(AND(G28<>"",G28<B28),AND(H28<>"",H28<B28),AND(I28<>"",I28<H28),AND(J28<>"",J28<I28)),"Date error","OK"))) -> OK
A29: L2028 | B29: 46090 | C29: School Visit | D29: Mass Communication | E29: IB | F29: Counselor F | G29: 46091 | K29: 2 | L29: =IF(J29<>"","Enrolled",IF(I29<>"","Admitted",IF(H29<>"","Applied",IF(G29<>"","Contacted","New")))) -> Contacted | M29: =IF(G29="","",G29-B29) -> 1 | N29: =IF(COUNTIF($A$2:A29,A29)>1,"Duplicate ID",IF(C29="","Missing source",IF(OR(AND(G29<>"",G29<B29),AND(H29<>"",H29<B29),AND(I29<>"",I29<H29),AND(J29<>"",J29<I29)),"Date error","OK"))) -> OK
A30: L2136 | B30: 46090 | C30: Meta Ads | D30: Business Administration | E30: American Diploma | F30: Counselor A | G30: 46091 | K30: 2 | L30: =IF(J30<>"","Enrolled",IF(I30<>"","Admitted",IF(H30<>"","Applied",IF(G30<>"","Contacted","New")))) -> Contacted | M30: =IF(G30="","",G30-B30) -> 1 | N30: =IF(COUNTIF($A$2:A30,A30)>1,"Duplicate ID",IF(C30="","Missing source",IF(OR(AND(G30<>"",G30<B30),AND(H30<>"",H30<B30),AND(I30<>"",I30<H30),AND(J30<>"",J30<I30)),"Date error","OK"))) -> OK
A31: L1168 | B31: 46091 | C31: Meta Ads | D31: Engineering | E31: Azhar/Other | F31: Counselor B | G31: 46092 | K31: 2 | L31: =IF(J31<>"","Enrolled",IF(I31<>"","Admitted",IF(H31<>"","Applied",IF(G31<>"","Contacted","New")))) -> Contacted | M31: =IF(G31="","",G31-B31) -> 1 | N31: =IF(COUNTIF($A$2:A31,A31)>1,"Duplicate ID",IF(C31="","Missing source",IF(OR(AND(G31<>"",G31<B31),AND(H31<>"",H31<B31),AND(I31<>"",I31<H31),AND(J31<>"",J31<I31)),"Date error","OK"))) -> OK
A32: L1404 | B32: 46091 | C32: Meta Ads | D32: Business Administration | E32: IB | F32: Counselor D | G32: 46093 | H32: 46103 | I32: 46112 | K32: 1 | L32: =IF(J32<>"","Enrolled",IF(I32<>"","Admitted",IF(H32<>"","Applied",IF(G32<>"","Contacted","New")))) -> Admitted | M32: =IF(G32="","",G32-B32) -> 2 | N32: =IF(COUNTIF($A$2:A32,A32)>1,"Duplicate ID",IF(C32="","Missing source",IF(OR(AND(G32<>"",G32<B32),AND(H32<>"",H32<B32),AND(I32<>"",I32<H32),AND(J32<>"",J32<I32)),"Date error","OK"))) -> OK
A33: L1702 | B33: 46091 | C33: Walk-in | D33: Business Administration | E33: National (Thanaweya Amma) | F33: Counselor E | G33: 46101 | K33: 2 | L33: =IF(J33<>"","Enrolled",IF(I33<>"","Admitted",IF(H33<>"","Applied",IF(G33<>"","Contacted","New")))) -> Contacted | M33: =IF(G33="","",G33-B33) -> 10 | N33: =IF(COUNTIF($A$2:A33,A33)>1,"Duplicate ID",IF(C33="","Missing source",IF(OR(AND(G33<>"",G33<B33),AND(H33<>"",H33<B33),AND(I33<>"",I33<H33),AND(J33<>"",J33<I33)),"Date error","OK"))) -> OK
A34: L2159 | B34: 46091 | C34: Meta Ads | D34: Business Administration | E34: National (Thanaweya Amma) | F34: Counselor B | G34: 46092 | K34: 3 | L34: =IF(J34<>"","Enrolled",IF(I34<>"","Admitted",IF(H34<>"","Applied",IF(G34<>"","Contacted","New")))) -> Contacted | M34: =IF(G34="","",G34-B34) -> 1 | N34: =IF(COUNTIF($A$2:A34,A34)>1,"Duplicate ID",IF(C34="","Missing source",IF(OR(AND(G34<>"",G34<B34),AND(H34<>"",H34<B34),AND(I34<>"",I34<H34),AND(J34<>"",J34<I34)),"Date error","OK"))) -> OK
A35: L2497 | B35: 46092 | C35: Referral | D35: Engineering | E35: National (Thanaweya Amma) | F35: Counselor C | G35: 46094 | K35: 3 | L35: =IF(J35<>"","Enrolled",IF(I35<>"","Admitted",IF(H35<>"","Applied",IF(G35<>"","Contacted","New")))) -> Contacted | M35: =IF(G35="","",G35-B35) -> 2 | N35: =IF(COUNTIF($A$2:A35,A35)>1,"Duplicate ID",IF(C35="","Missing source",IF(OR(AND(G35<>"",G35<B35),AND(H35<>"",H35<B35),AND(I35<>"",I35<H35),AND(J35<>"",J35<I35)),"Date error","OK"))) -> OK
A36: L2540 | B36: 46092 | C36: Meta Ads | D36: Business Administration | E36: National (Thanaweya Amma) | F36: Counselor B | G36: 46092 | K36: 1 | L36: =IF(J36<>"","Enrolled",IF(I36<>"","Admitted",IF(H36<>"","Applied",IF(G36<>"","Contacted","New")))) -> Contacted | M36: =IF(G36="","",G36-B36) -> 0 | N36: =IF(COUNTIF($A$2:A36,A36)>1,"Duplicate ID",IF(C36="","Missing source",IF(OR(AND(G36<>"",G36<B36),AND(H36<>"",H36<B36),AND(I36<>"",I36<H36),AND(J36<>"",J36<I36)),"Date error","OK"))) -> OK
A37: L1381 | B37: 46093 | C37: Referral | D37: Business Administration | E37: American Diploma | F37: Counselor D | G37: 46094 | K37: 5 | L37: =IF(J37<>"","Enrolled",IF(I37<>"","Admitted",IF(H37<>"","Applied",IF(G37<>"","Contacted","New")))) -> Contacted | M37: =IF(G37="","",G37-B37) -> 1 | N37: =IF(COUNTIF($A$2:A37,A37)>1,"Duplicate ID",IF(C37="","Missing source",IF(OR(AND(G37<>"",G37<B37),AND(H37<>"",H37<B37),AND(I37<>"",I37<H37),AND(J37<>"",J37<I37)),"Date error","OK"))) -> OK
A38: L1416 | B38: 46093 | C38: Google Ads | D38: Health Sciences | E38: American Diploma | F38: Counselor E | G38: 46099 | K38: 2 | L38: =IF(J38<>"","Enrolled",IF(I38<>"","Admitted",IF(H38<>"","Applied",IF(G38<>"","Contacted","New")))) -> Contacted | M38: =IF(G38="","",G38-B38) -> 6 | N38: =IF(COUNTIF($A$2:A38,A38)>1,"Duplicate ID",IF(C38="","Missing source",IF(OR(AND(G38<>"",G38<B38),AND(H38<>"",H38<B38),AND(I38<>"",I38<H38),AND(J38<>"",J38<I38)),"Date error","OK"))) -> OK
A39: L1974 | B39: 46093 | C39: Meta Ads | D39: Business Administration | E39: Azhar/Other | F39: Counselor D | G39: 46093 | K39: 3 | L39: =IF(J39<>"","Enrolled",IF(I39<>"","Admitted",IF(H39<>"","Applied",IF(G39<>"","Contacted","New")))) -> Contacted | M39: =IF(G39="","",G39-B39) -> 0 | N39: =IF(COUNTIF($A$2:A39,A39)>1,"Duplicate ID",IF(C39="","Missing source",IF(OR(AND(G39<>"",G39<B39),AND(H39<>"",H39<B39),AND(I39<>"",I39<H39),AND(J39<>"",J39<I39)),"Date error","OK"))) -> OK
A40: L1215 | B40: 46094 | C40: Meta Ads | D40: Computer Science | E40: National (Thanaweya Amma) | F40: Counselor A | G40: 46095 | K40: 0 | L40: =IF(J40<>"","Enrolled",IF(I40<>"","Admitted",IF(H40<>"","Applied",IF(G40<>"","Contacted","New")))) -> Contacted | M40: =IF(G40="","",G40-B40) -> 1 | N40: =IF(COUNTIF($A$2:A40,A40)>1,"Duplicate ID",IF(C40="","Missing source",IF(OR(AND(G40<>"",G40<B40),AND(H40<>"",H40<B40),AND(I40<>"",I40<H40),AND(J40<>"",J40<I40)),"Date error","OK"))) -> OK
...

Sheet Data_Quality
A1: Flag | B1: Records | C1: % of raw rows | D1: Rule
A2: OK | B2: =COUNTIF(Data!$N$2:$N$5000,A2) -> 1593 | C2: =IFERROR(B2/$B$8,0) -> 0.99252336 | D2: Used in every dashboard number
A3: Duplicate ID | B3: =COUNTIF(Data!$N$2:$N$5000,A3) -> 5 | C3: =IFERROR(B3/$B$8,0) -> 0.0031152648 | D3: lead_id already appeared on an earlier row (first occurrence kept)
A4: Missing source | B4: =COUNTIF(Data!$N$2:$N$5000,A4) -> 3 | C4: =IFERROR(B4/$B$8,0) -> 0.0018691589 | D4: Lead source is blank, so it cannot be attributed to a channel
A5: Date error | B5: =COUNTIF(Data!$N$2:$N$5000,A5) -> 4 | C5: =IFERROR(B5/$B$8,0) -> 0.0024922118 | D5: A stage date is earlier than the stage before it (e.g. application before lead creation)
A7: Excluded (total) | B7: =SUM(B3:B5) -> 12 | C7: =IFERROR(B7/$B$8,0) -> 0.0074766355 | D7: Records removed from the dashboard pending review
A8: Raw rows | B8: =COUNTA(Data!$A$2:$A$5000) -> 1605 | C8: =IFERROR(B8/$B$8,0) -> 1 | D8: All rows in the Data sheet
A9: Check | B9: =IF(B2+B7=B8,"Reconciles","CHECK") -> Reconciles | D9: OK + excluded must equal raw rows
A11: To review flagged rows: Data sheet > filter column N (dq_flag) > uncheck OK.

Sheet About
B1: Enrollment Funnel Dashboard (Excel)
B2: Purpose: portfolio project built for a Data Analyst application in a university enrollment team. Tracks lead → contacted → applied → admitted → enrolled.
B4: DATA
B5: • Fully SYNTHETIC: generated with a fixed random seed. No real students, schools or university records. Do not present it as real enrollment data.
B6: • 1,605 raw rows (1,600 leads + 5 deliberately duplicated rows) with 3 missing sources and 4 date errors injected to demonstrate data-quality handling.
B7: • Source-level conversion rates, counselor speeds and program admit rates are assumptions of the generator, chosen to look plausible. Findings describe this synthetic dataset only.
B8: • Snapshot date 30-Aug-2026: stage dates after this are blank, so recent leads have not had time to convert.
B10: DEFINITIONS
B11: • Lead → App % = applications / leads · App → Enrolled % = enrolled / applications · Lead → Enrolled % = enrolled / leads.
B12: • Days to first contact = first_contact_date − created_date (contacted leads only).
B13: • Stage (Data!L) = furthest stage reached, derived from which date columns are filled.
B15: HOW IT WORKS
... B18: • Forecast is a naive linear trend for illustration; it does not model seasonality.
